Workbook

Sheet Tableau_de_Bord
A1: TABLEAU DE BORD - ÉCHÉANCIER DES VENTES

Sheet Listes
A1: Listes & paramètres (modifiez ces listes pour alimenter les menus déroulants)
A2: Paramètre | B2: Valeur | D2: Clients | E2: Banques | F2: Moyens de paiement | G2: Oui/Non | H2: Type (B2B/B2C)
A3: Date de référence (modifiable) | B3: 46021 | D3: Client A (Exemple) | E3: BNP Paribas | F3: Virement | G3: Oui | H3: B2C
D4: Client B (Exemple) | E4: Société Générale | F4: CB | G4: Non | H4: B2B
A5: Note | B5: Astuce : vous pouvez changer la Date de référence pour simuler une autre date (tests de retards). | F5: Chèque
F6: Prélèvement

Sheet Ventes_Factures
A1: Échéancier de vente — Factures
A2: Saisie (bleu) : N° facture, Client, Type, Référence, Session, Dates, Montant, Litige.
A3: Calculé (gris) : encaissé, reste, statut, retard, aging.
A4: Astuce : triez/filtrez via l'entête (ligne 5).
A5: N° Facture | B5: Client | C5: Type | D5: Référence / Libellé | E5: Session (résumé) | F5: Date Facture | G5: Date d'échéance | H5: Montant TTC (€) | I5: Encaissé total (€) | J5: Reste à encaisser (€) | K5: Date dernier règlement | L5: Nb stagiaires | M5: Litige | N5: Statut | O5: Jours de retard | P5: Aging
A6: TAU_2025-362 | B6: 3919 | C6: CPF | D6: Factur M. Puche (TEST) | E6: CFBS | F6: 46021 | G6: 46052 | H6: 1215 | I6: =IF($A6="","",SUMIFS(Ventes_Encaissements!$D$6:$D$3005,Ventes_Encaissements!$B$6:$B$3005,$A6)) | J6: =IF($A6="","",$H6-$I6) | K6: =IF($A6="","",IF($I6=0,"",_xludf.AGGREGATE(14,6,Ventes_Encaissements!$C$6:$C$3005/(Ventes_Encaissements!$B$6:$B$3005=$A6),1))) | L6: 1 | N6: =IF($A6="","",IF($G6="","",IF($M6="Oui","Litige",IF($J6<=0,"Payé",IF($I6>0,"Partiel",IF(Listes!$B$3>$G6,"En retard","À échoir")))))) | O6: =IF($A6="","",IF(OR($G6="", $J6<=0),0,MAX(0,Listes!$B$3-$G6))) | P6: =IF($A6="","",IF($J6<=0,"Payé",IF($M6="Oui","Litige",IF($O6=0,"À échoir",IF($O6<=30,"0-30",IF($O6<=60,"31-60",IF($O6<=90,"61-90","90+")))))))
A7: TAU_2026-413 | B7: PAUL RICARD | C7: B2B | E7: 15/01/2026 au 16/01/2026 | F7: 49-01-2026 | H7: 465 | I7: =IF($A7="","",SUMIFS(Ventes_Encaissements!$D$6:$D$3005,Ventes_Encaissements!$B$6:$B$3005,$A7)) | J7: =IF($A7="","",$H7-$I7) | K7: =IF($A7="","",IF($I7=0,"",_xludf.AGGREGATE(14,6,Ventes_Encaissements!$C$6:$C$3005/(Ventes_Encaissements!$B$6:$B$3005=$A7),1))) | L7: =IF($A7="","",COUNTIFS(Ventes_Detail!$B$6:$B$3005,$A7)) | N7: =IF($A7="","",IF($G7="","",IF($M7="Oui","Litige",IF($J7<=0,"Payé",IF($I7>0,"Partiel",IF(Listes!$B$3>$G7,"En retard","À échoir")))))) | O7: =IF($A7="","",IF(OR($G7="", $J7<=0),0,MAX(0,Listes!$B$3-$G7))) | P7: =IF($A7="","",IF($J7<=0,"Payé",IF($M7="Oui","Litige",IF($O7=0,"À échoir",IF($O7<=30,"0-30",IF($O7<=60,"31-60",IF($O7<=90,"61-90","90+")))))))
A8: TAU_2026-487 | C8: B2B | E8: 03/02/2026 au 03/02/2026 | F8: 04-02-2026 | I8: =IF($A8="","",SUMIFS(Ventes_Encaissements!$D$6:$D$3005,Ventes_Encaissements!$B$6:$B$3005,$A8)) | J8: =IF($A8="","",$H8-$I8) | K8: =IF($A8="","",IF($I8=0,"",_xludf.AGGREGATE(14,6,Ventes_Encaissements!$C$6:$C$3005/(Ventes_Encaissements!$B$6:$B$3005=$A8),1))) | L8: =IF($A8="","",COUNTIFS(Ventes_Detail!$B$6:$B$3005,$A8)) | N8: =IF($A8="","",IF($G8="","",IF($M8="Oui","Litige",IF($J8<=0,"Payé",IF($I8>0,"Partiel",IF(Listes!$B$3>$G8,"En retard","À échoir")))))) | O8: =IF($A8="","",IF(OR($G8="", $J8<=0),0,MAX(0,Listes!$B$3-$G8))) | P8: =IF($A8="","",IF($J8<=0,"Payé",IF($M8="Oui","Litige",IF($O8=0,"À échoir",IF($O8<=30,"0-30",IF($O8<=60,"31-60",IF($O8<=90,"61-90","90+")))))))
A9: TAU_2026-487 | C9: B2B | E9: 03/02/2026 au 03/02/2026 | F9: 04-02-2026 | I9: =IF($A9="","",SUMIFS(Ventes_Encaissements!$D$6:$D$3005,Ventes_Encaissements!$B$6:$B$3005,$A9)) | J9: =IF($A9="","",$H9-$I9) | K9: =IF($A9="","",IF($I9=0,"",_xludf.AGGREGATE(14,6,Ventes_Encaissements!$C$6:$C$3005/(Ventes_Encaissements!$B$6:$B$3005=$A9),1))) | L9: =IF($A9="","",COUNTIFS(Ventes_Detail!$B$6:$B$3005,$A9)) | N9: =IF($A9="","",IF($G9="","",IF($M9="Oui","Litige",IF($J9<=0,"Payé",IF($I9>0,"Partiel",IF(Listes!$B$3>$G9,"En retard","À échoir")))))) | O9: =IF($A9="","",IF(OR($G9="", $J9<=0),0,MAX(0,Listes!$B$3-$G9))) | P9: =IF($A9="","",IF($J9<=0,"Payé",IF($M9="Oui","Litige",IF($O9=0,"À échoir",IF($O9<=30,"0-30",IF($O9<=60,"31-60",IF($O9<=90,"61-90","90+")))))))
A10: TAU_2026-487 | C10: B2B | E10: 03/02/2026 au 03/02/2026 | F10: 04-02-2026 | H10: 260 | I10: =IF($A10="","",SUMIFS(Ventes_Encaissements!$D$6:$D$3005,Ventes_Encaissements!$B$6:$B$3005,$A10)) | J10: =IF($A10="","",$H10-$I10) | K10: =IF($A10="","",IF($I10=0,"",_xludf.AGGREGATE(14,6,Ventes_Encaissements!$C$6:$C$3005/(Ventes_Encaissements!$B$6:$B$3005=$A10),1))) | L10: =IF($A10="","",COUNTIFS(Ventes_Detail!$B$6:$B$3005,$A10)) | N10: =IF($A10="","",IF($G10="","",IF($M10="Oui","Litige",IF($J10<=0,"Payé",IF($I10>0,"Partiel",IF(Listes!$B$3>$G10,"En retard","À échoir")))))) | O10: =IF($A10="","",IF(OR($G10="", $J10<=0),0,MAX(0,Listes!$B$3-$G10))) | P10: =IF($A10="","",IF($J10<=0,"Payé",IF($M10="Oui","Litige",IF($O10=0,"À échoir",IF($O10<=30,"0-30",IF($O10<=60,"31-60",IF($O10<=90,"61-90","90+")))))))
A11: TAU_2026-559 | C11: B2B | E11: 25/02/2026 au 25/02/2026 | F11: 25/02/2026 | H11: 450 | I11: =IF($A11="","",SUMIFS(Ventes_Encaissements!$D$6:$D$3005,Ventes_Encaissements!$B$6:$B$3005,$A11)) | J11: =IF($A11="","",$H11-$I11) | K11: =IF($A11="","",IF($I11=0,"",_xludf.AGGREGATE(14,6,Ventes_Encaissements!$C$6:$C$3005/(Ventes_Encaissements!$B$6:$B$3005=$A11),1))) | L11: =IF($A11="","",COUNTIFS(Ventes_Detail!$B$6:$B$3005,$A11)) | N11: =IF($A11="","",IF($G11="","",IF($M11="Oui","Litige",IF($J11<=0,"Payé",IF($I11>0,"Partiel",IF(Listes!$B$3>$G11,"En retard","À échoir")))))) | O11: =IF($A11="","",IF(OR($G11="", $J11<=0),0,MAX(0,Listes!$B$3-$G11))) | P11: =IF($A11="","",IF($J11<=0,"Payé",IF($M11="Oui","Litige",IF($O11=0,"À échoir",IF($O11<=30,"0-30",IF($O11<=60,"31-60",IF($O11<=90,"61-90","90+")))))))
A12: TAU_2026-559 | C12: B2B | E12: 25/02/2026 au 25/02/2026 | F12: 25-02-2026 | G12: 25-02-2026 | H12: 450 | I12: =IF($A12="","",SUMIFS(Ventes_Encaissements!$D$6:$D$3005,Ventes_Encaissements!$B$6:$B$3005,$A12)) | J12: =IF($A12="","",$H12-$I12) | K12: =IF($A12="","",IF($I12=0,"",_xludf.AGGREGATE(14,6,Ventes_Encaissements!$C$6:$C$3005/(Ventes_Encaissements!$B$6:$B$3005=$A12),1))) | L12: =IF($A12="","",COUNTIFS(Ventes_Detail!$B$6:$B$3005,$A12)) | N12: =IF($A12="","",IF($G12="","",IF($M12="Oui","Litige",IF($J12<=0,"Payé",IF($I12>0,"Partiel",IF(Listes!$B$3>$G12,"En retard","À échoir")))))) | O12: =IF($A12="","",IF(OR($G12="", $J12<=0),0,MAX(0,Listes!$B$3-$G12))) | P12: =IF($A12="","",IF($J12<=0,"Payé",IF($M12="Oui","Litige",IF($O12=0,"À échoir",IF($O12<=30,"0-30",IF($O12<=60,"31-60",IF($O12<=90,"61-90","90+")))))))
A13: TAU_2026-409 | B13: PORQUEROLLES MARINE SERVICES | C13: B2B | E13: 15/01/2026 au 16/01/2026 | F13: 46041 | G13: 46041 | H13: 465 | I13: =IF($A13="","",SUMIFS(Ventes_Encaissements!$D$6:$D$3005,Ventes_Encaissements!$B$6:$B$3005,$A13)) | J13: =IF($A13="","",$H13-$I13) | K13: =IF($A13="","",IF($I13=0,"",_xludf.AGGREGATE(14,6,Ventes_Encaissements!$C$6:$C$3005/(Ventes_Encaissements!$B$6:$B$3005=$A13),1))) | L13: =IF($A13="","",COUNTIFS(Ventes_Detail!$B$6:$B$3005,$A13)) | N13: =IF($A13="","",IF($G13="","",IF($M13="Oui","Litige",IF($J13<=0,"Payé",IF($I13>0,"Partiel",IF(Listes!$B$3>$G13,"En retard","À échoir")))))) | O13: =IF($A13="","",IF(OR($G13="", $J13<=0),0,MAX(0,Listes!$B$3-$G13))) | P13: =IF($A13="","",IF($J13<=0,"Payé",IF($M13="Oui","Litige",IF($O13=0,"À échoir",IF($O13<=30,"0-30",IF($O13<=60,"31-60",IF($O13<=90,"61-90","90+")))))))
A14: TAU_2026-397 | B14: Syndicat Professionnel des Pilotes de Marseille et du Golfe de Fos | C14: B2B | F14: 46034 | G14: 46064 | H14: 5.6 | I14: =IF($A14="","",SUMIFS(Ventes_Encaissements!$D$6:$D$3005,Ventes_Encaissements!$B$6:$B$3005,$A14)) | J14: =IF($A14="","",$H14-$I14) | K14: =IF($A14="","",IF($I14=0,"",_xludf.AGGREGATE(14,6,Ventes_Encaissements!$C$6:$C$3005/(Ventes_Encaissements!$B$6:$B$3005=$A14),1))) | L14: =IF($A14="","",COUNTIFS(Ventes_Detail!$B$6:$B$3005,$A14)) | N14: =IF($A14="","",IF($G14="","",IF($M14="Oui","Litige",IF($J14<=0,"Payé",IF($I14>0,"Partiel",IF(Listes!$B$3>$G14,"En retard","À échoir")))))) | O14: =IF($A14="","",IF(OR($G14="", $J14<=0),0,MAX(0,Listes!$B$3-$G14))) | P14: =IF($A14="","",IF($J14<=0,"Payé",IF($M14="Oui","Litige",IF($O14=0,"À échoir",IF($O14<=30,"0-30",IF($O14<=60,"31-60",IF($O14<=90,"61-90","90+")))))))
A15: TAU_2026-395 | C15: B2B | E15: 09/01/2026 au 09/01/2026 | F15: 46034 | G15: 46034 | H15: 260 | I15: =IF($A15="","",SUMIFS(Ventes_Encaissements!$D$6:$D$3005,Ventes_Encaissements!$B$6:$B$3005,$A15)) | J15: =IF($A15="","",$H15-$I15) | K15: =IF($A15="","",IF($I15=0,"",_xludf.AGGREGATE(14,6,Ventes_Encaissements!$C$6:$C$3005/(Ventes_Encaissements!$B$6:$B$3005=$A15),1))) | L15: =IF($A15="","",COUNTIFS(Ventes_Detail!$B$6:$B$3005,$A15)) | N15: =IF($A15="","",IF($G15="","",IF($M15="Oui","Litige",IF($J15<=0,"Payé",IF($I15>0,"Partiel",IF(Listes!$B$3>$G15,"En retard","À échoir")))))) | O15: =IF($A15="","",IF(OR($G15="", $J15<=0),0,MAX(0,Listes!$B$3-$G15))) | P15: =IF($A15="","",IF($J15<=0,"Payé",IF($M15="Oui","Litige",IF($O15=0,"À échoir",IF($O15<=30,"0-30",IF($O15<=60,"31-60",IF($O15<=90,"61-90","90+")))))))
A16: TAU_2026-391 | B16: POLE TAUROENTUM | C16: B2B | E16: 09/01/2026 au 09/01/2026 | F16: 46034 | G16: 46034 | H16: 520 | I16: =IF($A16="","",SUMIFS(Ventes_Encaissements!$D$6:$D$3005,Ventes_Encaissements!$B$6:$B$3005,$A16)) | J16: =IF($A16="","",$H16-$I16) | K16: =IF($A16="","",IF($I16=0,"",_xludf.AGGREGATE(14,6,Ventes_Encaissements!$C$6:$C$3005/(Ventes_Encaissements!$B$6:$B$3005=$A16),1))) | L16: =IF($A16="","",COUNTIFS(Ventes_Detail!$B$6:$B$3005,$A16)) | N16: =IF($A16="","",IF($G16="","",IF($M16="Oui","Litige",IF($J16<=0,"Payé",IF($I16>0,"Partiel",IF(Listes!$B$3>$G16,"En retard","À échoir")))))) | O16: =IF($A16="","",IF(OR($G16="", $J16<=0),0,MAX(0,Listes!$B$3-$G16))) | P16: =IF($A16="","",IF($J16<=0,"Payé",IF($M16="Oui","Litige",IF($O16=0,"À échoir",IF($O16<=30,"0-30",IF($O16<=60,"31-60",IF($O16<=90,"61-90","90+")))))))
A17: TAU_2025-343 | B17: POLE TAUROENTUM | C17: B2B | E17: 27/10/2025 au 19/12/2025 | F17: 46014 | G17: 46014 | H17: 3.05 | I17: =IF($A17="","",SUMIFS(Ventes_Encaissements!$D$6:$D$3005,Ventes_Encaissements!$B$6:$B$3005,$A17)) | J17: =IF($A17="","",$H17-$I17) | K17: =IF($A17="","",IF($I17=0,"",_xludf.AGGREGATE(14,6,Ventes_Encaissements!$C$6:$C$3005/(Ventes_Encaissements!$B$6:$B$3005=$A17),1))) | L17: =IF($A17="","",COUNTIFS(Ventes_Detail!$B$6:$B$3005,$A17)) | N17: =IF($A17="","",IF($G17="","",IF($M17="Oui","Litige",IF($J17<=0,"Payé",IF($I17>0,"Partiel",IF(Listes!$B$3>$G17,"En retard","À échoir")))))) | O17: =IF($A17="","",IF(OR($G17="", $J17<=0),0,MAX(0,Listes!$B$3-$G17))) | P17: =IF($A17="","",IF($J17<=0,"Payé",IF($M17="Oui","Litige",IF($O17=0,"À échoir",IF($O17<=30,"0-30",IF($O17<=60,"31-60",IF($O17<=90,"61-90","90+")))))))
A18: TAU_2025-339 | B18: CPF | C18: CPF | E18: 27/10/2025 au 19/12/2025 | F18: 46013 | G18: 46013 | H18: 3.05 | I18: =IF($A18="","",SUMIFS(Ventes_Encaissements!$D$6:$D$3005,Ventes_Encaissements!$B$6:$B$3005,$A18)) | J18: =IF($A18="","",$H18-$I18) | K18: =IF($A18="","",IF($I18=0,"",_xludf.AGGREGATE(14,6,Ventes_Encaissements!$C$6:$C$3005/(Ventes_Encaissements!$B$6:$B$3005=$A18),1))) | L18: =IF($A18="","",COUNTIFS(Ventes_Detail!$B$6:$B$3005,$A18)) | N18: =IF($A18="","",IF($G18="","",IF($M18="Oui","Litige",IF($J18<=0,"Payé",IF($I18>0,"Partiel",IF(Listes!$B$3>$G18,"En retard","À échoir")))))) | O18: =IF($A18="","",IF(OR($G18="", $J18<=0),0,MAX(0,Listes!$B$3-$G18))) | P18: =IF($A18="","",IF($J18<=0,"Payé",IF($M18="Oui","Litige",IF($O18=0,"À échoir",IF($O18<=30,"0-30",IF($O18<=60,"31-60",IF($O18<=90,"61-90","90+")))))))
A19: TAU_2025-337 | B19: CPF | C19: CPF | E19: 27/10/2025 au 19/12/2025 | F19: 46013 | G19: 46013 | H19: 3.05 | I19: =IF($A19="","",SUMIFS(Ventes_Encaissements!$D$6:$D$3005,Ventes_Encaissements!$B$6:$B$3005,$A19)) | J19: =IF($A19="","",$H19-$I19) | K19: =IF($A19="","",IF($I19=0,"",_xludf.AGGREGATE(14,6,Ventes_Encaissements!$C$6:$C$3005/(Ventes_Encaissements!$B$6:$B$3005=$A19),1))) | L19: =IF($A19="","",COUNTIFS(Ventes_Detail!$B$6:$B$3005,$A19)) | N19: =IF($A19="","",IF($G19="","",IF($M19="Oui","Litige",IF($J19<=0,"Payé",IF($I19>0,"Partiel",IF(Listes!$B$3>$G19,"En retard","À échoir")))))) | O19: =IF($A19="","",IF(OR($G19="", $J19<=0),0,MAX(0,Listes!$B$3-$G19))) | P19: =IF($A19="","",IF($J19<=0,"Payé",IF($M19="Oui","Litige",IF($O19=0,"À échoir",IF($O19<=30,"0-30",IF($O19<=60,"31-60",IF($O19<=90,"61-90","90+")))))))
A20: TAU_2025-335 | B20: CPF | C20: CPF | E20: 18/12/2025 au 19/12/2025 | F20: 46013 | G20: 46013 | H20: 465 | I20: =IF($A20="","",SUMIFS(Ventes_Encaissements!$D$6:$D$3005,Ventes_Encaissements!$B$6:$B$3005,$A20)) | J20: =IF($A20="","",$H20-$I20) | K20: =IF($A20="","",IF($I20=0,"",_xludf.AGGREGATE(14,6,Ventes_Encaissements!$C$6:$C$3005/(Ventes_Encaissements!$B$6:$B$3005=$A20),1))) | L20: =IF($A20="","",COUNTIFS(Ventes_Detail!$B$6:$B$3005,$A20)) | N20: =IF($A20="","",IF($G20="","",IF($M20="Oui","Litige",IF($J20<=0,"Payé",IF($I20>0,"Partiel",IF(Listes!$B$3>$G20,"En retard","À échoir")))))) | O20: =IF($A20="","",IF(OR($G20="", $J20<=0),0,MAX(0,Listes!$B$3-$G20))) | P20: =IF($A20="","",IF($J20<=0,"Payé",IF($M20="Oui","Litige",IF($O20=0,"À échoir",IF($O20<=30,"0-30",IF($O20<=60,"31-60",IF($O20<=90,"61-90","90+")))))))
A21: TAU_2025-333 | B21: POLE TAUROENTUM | C21: B2B | E21: 18/12/2025 au 19/12/2025 | F21: 46013 | G21: 46013 | H21: 465 | I21: =IF($A21="","",SUMIFS(Ventes_Encaissements!$D$6:$D$3005,Ventes_Encaissements!$B$6:$B$3005,$A21)) | J21: =IF($A21="","",$H21-$I21) | K21: =IF($A21="","",IF($I21=0,"",_xludf.AGGREGATE(14,6,Ventes_Encaissements!$C$6:$C$3005/(Ventes_Encaissements!$B$6:$B$3005=$A21),1))) | L21: =IF($A21="","",COUNTIFS(Ventes_Detail!$B$6:$B$3005,$A21)) | N21: =IF($A21="","",IF($G21="","",IF($M21="Oui","Litige",IF($J21<=0,"Payé",IF($I21>0,"Partiel",IF(Listes!$B$3>$G21,"En retard","À échoir")))))) | O21: =IF($A21="","",IF(OR($G21="", $J21<=0),0,MAX(0,Listes!$B$3-$G21))) | P21: =IF($A21="","",IF($J21<=0,"Payé",IF($M21="Oui","Litige",IF($O21=0,"À échoir",IF($O21<=30,"0-30",IF($O21<=60,"31-60",IF($O21<=90,"61-90","90+")))))))
A22: TAU_2025-328 | B22: CPF | C22: CPF | E22: 27/10/2025 au 19/12/2025 | F22: 46013 | G22: 46013 | H22: 3.05 | I22: =IF($A22="","",SUMIFS(Ventes_Encaissements!$D$6:$D$3005,Ventes_Encaissements!$B$6:$B$3005,$A22)) | J22: =IF($A22="","",$H22-$I22) | K22: =IF($A22="","",IF($I22=0,"",_xludf.AGGREGATE(14,6,Ventes_Encaissements!$C$6:$C$3005/(Ventes_Encaissements!$B$6:$B$3005=$A22),1))) | L22: =IF($A22="","",COUNTIFS(Ventes_Detail!$B$6:$B$3005,$A22)) | N22: =IF($A22="","",IF($G22="","",IF($M22="Oui","Litige",IF($J22<=0,"Payé",IF($I22>0,"Partiel",IF(Listes!$B$3>$G22,"En retard","À échoir")))))) | O22: =IF($A22="","",IF(OR($G22="", $J22<=0),0,MAX(0,Listes!$B$3-$G22))) | P22: =IF($A22="","",IF($J22<=0,"Payé",IF($M22="Oui","Litige",IF($O22=0,"À échoir",IF($O22<=30,"0-30",IF($O22<=60,"31-60",IF($O22<=90,"61-90","90+")))))))
A23: TAU_2025-325 | B23: CPF | C23: CPF | E23: 18/12/2025 au 19/12/2025 | F23: 46013 | G23: 46013 | H23: 465 | I23: =IF($A23="","",SUMIFS(Ventes_Encaissements!$D$6:$D$3005,Ventes_Encaissements!$B$6:$B$3005,$A23)) | J23: =IF($A23="","",$H23-$I23) | K23: =IF($A23="","",IF($I23=0,"",_xludf.AGGREGATE(14,6,Ventes_Encaissements!$C$6:$C$3005/(Ventes_Encaissements!$B$6:$B$3005=$A23),1))) | L23: =IF($A23="","",COUNTIFS(Ventes_Detail!$B$6:$B$3005,$A23)) | N23: =IF($A23="","",IF($G23="","",IF($M23="Oui","Litige",IF($J23<=0,"Payé",IF($I23>0,"Partiel",IF(Listes!$B$3>$G23,"En retard","À échoir")))))) | O23: =IF($A23="","",IF(OR($G23="", $J23<=0),0,MAX(0,Listes!$B$3-$G23))) | P23: =IF($A23="","",IF($J23<=0,"Payé",IF($M23="Oui","Litige",IF($O23=0,"À échoir",IF($O23<=30,"0-30",IF($O23<=60,"31-60",IF($O23<=90,"61-90","90+")))))))
A24: TAU_2025-321 | B24: CPF | C24: CPF | E24: 18/12/2025 au 19/12/2025 | F24: 46013 | G24: 46013 | H24: 465 | I24: =IF($A24="","",SUMIFS(Ventes_Encaissements!$D$6:$D$3005,Ventes_Encaissements!$B$6:$B$3005,$A24)) | J24: =IF($A24="","",$H24-$I24) | K24: =IF($A24="","",IF($I24=0,"",_xludf.AGGREGATE(14,6,Ventes_Encaissements!$C$6:$C$3005/(Ventes_Encaissements!$B$6:$B$3005=$A24),1))) | L24: =IF($A24="","",COUNTIFS(Ventes_Detail!$B$6:$B$3005,$A24)) | N24: =IF($A24="","",IF($G24="","",IF($M24="Oui","Litige",IF($J24<=0,"Payé",IF($I24>0,"Partiel",IF(Listes!$B$3>$G24,"En retard","À échoir")))))) | O24: =IF($A24="","",IF(OR($G24="", $J24<=0),0,MAX(0,Listes!$B$3-$G24))) | P24: =IF($A24="","",IF($J24<=0,"Payé",IF($M24="Oui","Litige",IF($O24=0,"À échoir",IF($O24<=30,"0-30",IF($O24<=60,"31-60",IF($O24<=90,"61-90","90+")))))))
A25: TAU_2025-320 | B25: CPF | C25: CPF | E25: 18/12/2025 au 19/12/2025 | F25: 46013 | G25: 46013 | H25: 465 | I25: =IF($A25="","",SUMIFS(Ventes_Encaissements!$D$6:$D$3005,Ventes_Encaissements!$B$6:$B$3005,$A25)) | J25: =IF($A25="","",$H25-$I25) | K25: =IF($A25="","",IF($I25=0,"",_xludf.AGGREGATE(14,6,Ventes_Encaissements!$C$6:$C$3005/(Ventes_Encaissements!$B$6:$B$3005=$A25),1))) | L25: =IF($A25="","",COUNTIFS(Ventes_Detail!$B$6:$B$3005,$A25)) | N25: =IF($A25="","",IF($G25="","",IF($M25="Oui","Litige",IF($J25<=0,"Payé",IF($I25>0,"Partiel",IF(Listes!$B$3>$G25,"En retard","À échoir")))))) | O25: =IF($A25="","",IF(OR($G25="", $J25<=0),0,MAX(0,Listes!$B$3-$G25))) | P25: =IF($A25="","",IF($J25<=0,"Payé",IF($M25="Oui","Litige",IF($O25=0,"À échoir",IF($O25<=30,"0-30",IF($O25<=60,"31-60",IF($O25<=90,"61-90","90+")))))))
A26: TAU_2025-318 | B26: POLE TAUROENTUM | C26: B2B | E26: 11/12/2025 au 11/12/2025 | F26: 46010 | G26: 46010 | H26: 260 | I26: =IF($A26="","",SUMIFS(Ventes_Encaissements!$D$6:$D$3005,Ventes_Encaissements!$B$6:$B$3005,$A26)) | J26: =IF($A26="","",$H26-$I26) | K26: =IF($A26="","",IF($I26=0,"",_xludf.AGGREGATE(14,6,Ventes_Encaissements!$C$6:$C$3005/(Ventes_Encaissements!$B$6:$B$3005=$A26),1))) | L26: =IF($A26="","",COUNTIFS(Ventes_Detail!$B$6:$B$3005,$A26)) | N26: =IF($A26="","",IF($G26="","",IF($M26="Oui","Litige",IF($J26<=0,"Payé",IF($I26>0,"Partiel",IF(Listes!$B$3>$G26,"En retard","À échoir")))))) | O26: =IF($A26="","",IF(OR($G26="", $J26<=0),0,MAX(0,Listes!$B$3-$G26))) | P26: =IF($A26="","",IF($J26<=0,"Payé",IF($M26="Oui","Litige",IF($O26=0,"À échoir",IF($O26<=30,"0-30",IF($O26<=60,"31-60",IF($O26<=90,"61-90","90+")))))))
A27: TAU_2025-306 | B27: POLE TAUROENTUM | C27: B2B | E27: 11/12/2025 au 11/12/2025 | F27: 46010 | G27: 46040 | H27: 260 | I27: =IF($A27="","",SUMIFS(Ventes_Encaissements!$D$6:$D$3005,Ventes_Encaissements!$B$6:$B$3005,$A27)) | J27: =IF($A27="","",$H27-$I27) | K27: =IF($A27="","",IF($I27=0,"",_xludf.AGGREGATE(14,6,Ventes_Encaissements!$C$6:$C$3005/(Ventes_Encaissements!$B$6:$B$3005=$A27),1))) | L27: =IF($A27="","",COUNTIFS(Ventes_Detail!$B$6:$B$3005,$A27)) | N27: =IF($A27="","",IF($G27="","",IF($M27="Oui","Litige",IF($J27<=0,"Payé",IF($I27>0,"Partiel",IF(Listes!$B$3>$G27,"En retard","À échoir")))))) | O27: =IF($A27="","",IF(OR($G27="", $J27<=0),0,MAX(0,Listes!$B$3-$G27))) | P27: =IF($A27="","",IF($J27<=0,"Payé",IF($M27="Oui","Litige",IF($O27=0,"À échoir",IF($O27<=30,"0-30",IF($O27<=60,"31-60",IF($O27<=90,"61-90","90+")))))))
A28: TAU_2025-315 | C28: B2B | E28: 16/12/2025 au 16/12/2025 | F28: 46009 | G28: 46039 | H28: 2.4 | I28: =IF($A28="","",SUMIFS(Ventes_Encaissements!$D$6:$D$3005,Ventes_Encaissements!$B$6:$B$3005,$A28)) | J28: =IF($A28="","",$H28-$I28) | K28: =IF($A28="","",IF($I28=0,"",_xludf.AGGREGATE(14,6,Ventes_Encaissements!$C$6:$C$3005/(Ventes_Encaissements!$B$6:$B$3005=$A28),1))) | L28: =IF($A28="","",COUNTIFS(Ventes_Detail!$B$6:$B$3005,$A28)) | N28: =IF($A28="","",IF($G28="","",IF($M28="Oui","Litige",IF($J28<=0,"Payé",IF($I28>0,"Partiel",IF(Listes!$B$3>$G28,"En retard","À échoir")))))) | O28: =IF($A28="","",IF(OR($G28="", $J28<=0),0,MAX(0,Listes!$B$3-$G28))) | P28: =IF($A28="","",IF($J28<=0,"Payé",IF($M28="Oui","Litige",IF($O28=0,"À échoir",IF($O28<=30,"0-30",IF($O28<=60,"31-60",IF($O28<=90,"61-90","90+")))))))
A29: TAU_2025-67 | B29: ACPM | C29: B2B | F29: 45943 | G29: 45943 | H29: 1.5 | I29: =IF($A29="","",SUMIFS(Ventes_Encaissements!$D$6:$D$3005,Ventes_Encaissements!$B$6:$B$3005,$A29)) | J29: =IF($A29="","",$H29-$I29) | K29: =IF($A29="","",IF($I29=0,"",_xludf.AGGREGATE(14,6,Ventes_Encaissements!$C$6:$C$3005/(Ventes_Encaissements!$B$6:$B$3005=$A29),1))) | L29: =IF($A29="","",COUNTIFS(Ventes_Detail!$B$6:$B$3005,$A29)) | N29: =IF($A29="","",IF($G29="","",IF($M29="Oui","Litige",IF($J29<=0,"Payé",IF($I29>0,"Partiel",IF(Listes!$B$3>$G29,"En retard","À échoir")))))) | O29: =IF($A29="","",IF(OR($G29="", $J29<=0),0,MAX(0,Listes!$B$3-$G29))) | P29: =IF($A29="","",IF($J29<=0,"Payé",IF($M29="Oui","Litige",IF($O29=0,"À échoir",IF($O29<=30,"0-30",IF($O29<=60,"31-60",IF($O29<=90,"61-90","90+")))))))
A30: TAU_2025-41 | C30: B2B | E30: 19/09/2025 au 19/09/2025 | F30: 45922 | G30: 45922 | H30: 260 | I30: =IF($A30="","",SUMIFS(Ventes_Encaissements!$D$6:$D$3005,Ventes_Encaissements!$B$6:$B$3005,$A30)) | J30: =IF($A30="","",$H30-$I30) | K30: =IF($A30="","",IF($I30=0,"",_xludf.AGGREGATE(14,6,Ventes_Encaissements!$C$6:$C$3005/(Ventes_Encaissements!$B$6:$B$3005=$A30),1))) | L30: =IF($A30="","",COUNTIFS(Ventes_Detail!$B$6:$B$3005,$A30)) | N30: =IF($A30="","",IF($G30="","",IF($M30="Oui","Litige",IF($J30<=0,"Payé",IF($I30>0,"Partiel",IF(Listes!$B$3>$G30,"En retard","À échoir")))))) | O30: =IF($A30="","",IF(OR($G30="", $J30<=0),0,MAX(0,Listes!$B$3-$G30))) | P30: =IF($A30="","",IF($J30<=0,"Payé",IF($M30="Oui","Litige",IF($O30=0,"À échoir",IF($O30<=30,"0-30",IF($O30<=60,"31-60",IF($O30<=90,"61-90","90+")))))))
A31: TAU_2026-25 | C31: B2B | E31: 11/09/2025 au 12/09/2025 | F31: 45915 | G31: 45915 | H31: 150 | I31: =IF($A31="","",SUMIFS(Ventes_Encaissements!$D$6:$D$3005,Ventes_Encaissements!$B$6:$B$3005,$A31)) | J31: =IF($A31="","",$H31-$I31) | K31: =IF($A31="","",IF($I31=0,"",_xludf.AGGREGATE(14,6,Ventes_Encaissements!$C$6:$C$3005/(Ventes_Encaissements!$B$6:$B$3005=$A31),1))) | L31: =IF($A31="","",COUNTIFS(Ventes_Detail!$B$6:$B$3005,$A31)) | N31: =IF($A31="","",IF($G31="","",IF($M31="Oui","Litige",IF($J31<=0,"Payé",IF($I31>0,"Partiel",IF(Listes!$B$3>$G31,"En retard","À échoir")))))) | O31: =IF($A31="","",IF(OR($G31="", $J31<=0),0,MAX(0,Listes!$B$3-$G31))) | P31: =IF($A31="","",IF($J31<=0,"Payé",IF($M31="Oui","Litige",IF($O31=0,"À échoir",IF($O31<=30,"0-30",IF($O31<=60,"31-60",IF($O31<=90,"61-90","90+")))))))
A32: TAU_2025-19 | C32: B2B | F32: 45912 | G32: 45912 | H32: 150 | I32: =IF($A32="","",SUMIFS(Ventes_Encaissements!$D$6:$D$3005,Ventes_Encaissements!$B$6:$B$3005,$A32)) | J32: =IF($A32="","",$H32-$I32) | K32: =IF($A32="","",IF($I32=0,"",_xludf.AGGREGATE(14,6,Ventes_Encaissements!$C$6:$C$3005/(Ventes_Encaissements!$B$6:$B$3005=$A32),1))) | L32: =IF($A32="","",COUNTIFS(Ventes_Detail!$B$6:$B$3005,$A32)) | N32: =IF($A32="","",IF($G32="","",IF($M32="Oui","Litige",IF($J32<=0,"Payé",IF($I32>0,"Partiel",IF(Listes!$B$3>$G32,"En retard","À échoir")))))) | O32: =IF($A32="","",IF(OR($G32="", $J32<=0),0,MAX(0,Listes!$B$3-$G32))) | P32: =IF($A32="","",IF($J32<=0,"Payé",IF($M32="Oui","Litige",IF($O32=0,"À échoir",IF($O32<=30,"0-30",IF($O32<=60,"31-60",IF($O32<=90,"61-90","90+")))))))
A33: TAU_2025-14 | B33: Syndicat Professionnel des Pilotes de Marseille et du Golfe de Fos | C33: B2B | E33: 08/09/2025 au 09/09/1202 | F33: 45911 | G33: 45911 | H33: 450 | I33: =IF($A33="","",SUMIFS(Ventes_Encaissements!$D$6:$D$3005,Ventes_Encaissements!$B$6:$B$3005,$A33)) | J33: =IF($A33="","",$H33-$I33) | K33: =IF($A33="","",IF($I33=0,"",_xludf.AGGREGATE(14,6,Ventes_Encaissements!$C$6:$C$3005/(Ventes_Encaissements!$B$6:$B$3005=$A33),1))) | L33: =IF($A33="","",COUNTIFS(Ventes_Detail!$B$6:$B$3005,$A33)) | N33: =IF($A33="","",IF($G33="","",IF($M33="Oui","Litige",IF($J33<=0,"Payé",IF($I33>0,"Partiel",IF(Listes!$B$3>$G33,"En retard","À échoir")))))) | O33: =IF($A33="","",IF(OR($G33="", $J33<=0),0,MAX(0,Listes!$B$3-$G33))) | P33: =IF($A33="","",IF($J33<=0,"Payé",IF($M33="Oui","Litige",IF($O33=0,"À échoir",IF($O33<=30,"0-30",IF($O33<=60,"31-60",IF($O33<=90,"61-90","90+")))))))
I34: =IF($A34="","",SUMIFS(Ventes_Encaissements!$D$6:$D$3005,Ventes_Encaissements!$B$6:$B$3005,$A34)) | J34: =IF($A34="","",$H34-$I34) | K34: =IF($A34="","",IF($I34=0,"",_xludf.AGGREGATE(14,6,Ventes_Encaissements!$C$6:$C$3005/(Ventes_Encaissements!$B$6:$B$3005=$A34),1))) | L34: =IF($A34="","",COUNTIFS(Ventes_Detail!$B$6:$B$3005,$A34)) | N34: =IF($A34="","",IF($G34="","",IF($M34="Oui","Litige",IF($J34<=0,"Payé",IF($I34>0,"Partiel",IF(Listes!$B$3>$G34,"En retard","À échoir")))))) | O34: =IF($A34="","",IF(OR($G34="", $J34<=0),0,MAX(0,Listes!$B$3-$G34))) | P34: =IF($A34="","",IF($J34<=0,"Payé",IF($M34="Oui","Litige",IF($O34=0,"À échoir",IF($O34<=30,"0-30",IF($O34<=60,"31-60",IF($O34<=90,"61-90","90+")))))))
I35: =IF($A35="","",SUMIFS(Ventes_Encaissements!$D$6:$D$3005,Ventes_Encaissements!$B$6:$B$3005,$A35)) | J35: =IF($A35="","",$H35-$I35) | K35: =IF($A35="","",IF($I35=0,"",_xludf.AGGREGATE(14,6,Ventes_Encaissements!$C$6:$C$3005/(Ventes_Encaissements!$B$6:$B$3005=$A35),1))) | L35: =IF($A35="","",COUNTIFS(Ventes_Detail!$B$6:$B$3005,$A35)) | N35: =IF($A35="","",IF($G35="","",IF($M35="Oui","Litige",IF($J35<=0,"Payé",IF($I35>0,"Partiel",IF(Listes!$B$3>$G35,"En retard","À échoir")))))) | O35: =IF($A35="","",IF(OR($G35="", $J35<=0),0,MAX(0,Listes!$B$3-$G35))) | P35: =IF($A35="","",IF($J35<=0,"Payé",IF($M35="Oui","Litige",IF($O35=0,"À échoir",IF($O35<=30,"0-30",IF($O35<=60,"31-60",IF($O35<=90,"61-90","90+")))))))
I36: =IF($A36="","",SUMIFS(Ventes_Encaissements!$D$6:$D$3005,Ventes_Encaissements!$B$6:$B$3005,$A36)) | J36: =IF($A36="","",$H36-$I36) | K36: =IF($A36="","",IF($I36=0,"",_xludf.AGGREGATE(14,6,Ventes_Encaissements!$C$6:$C$3005/(Ventes_Encaissements!$B$6:$B$3005=$A36),1))) | L36: =IF($A36="","",COUNTIFS(Ventes_Detail!$B$6:$B$3005,$A36)) | N36: =IF($A36="","",IF($G36="","",IF($M36="Oui","Litige",IF($J36<=0,"Payé",IF($I36>0,"Partiel",IF(Listes!$B$3>$G36,"En retard","À échoir")))))) | O36: =IF($A36="","",IF(OR($G36="", $J36<=0),0,MAX(0,Listes!$B$3-$G36))) | P36: =IF($A36="","",IF($J36<=0,"Payé",IF($M36="Oui","Litige",IF($O36=0,"À échoir",IF($O36<=30,"0-30",IF($O36<=60,"31-60",IF($O36<=90,"61-90","90+")))))))
I37: =IF($A37="","",SUMIFS(Ventes_Encaissements!$D$6:$D$3005,Ventes_Encaissements!$B$6:$B$3005,$A37)) | J37: =IF($A37="","",$H37-$I37) | K37: =IF($A37="","",IF($I37=0,"",_xludf.AGGREGATE(14,6,Ventes_Encaissements!$C$6:$C$3005/(Ventes_Encaissements!$B$6:$B$3005=$A37),1))) | L37: =IF($A37="","",COUNTIFS(Ventes_Detail!$B$6:$B$3005,$A37)) | N37: =IF($A37="","",IF($G37="","",IF($M37="Oui","Litige",IF($J37<=0,"Payé",IF($I37>0,"Partiel",IF(Listes!$B$3>$G37,"En retard","À échoir")))))) | O37: =IF($A37="","",IF(OR($G37="", $J37<=0),0,MAX(0,Listes!$B$3-$G37))) | P37: =IF($A37="","",IF($J37<=0,"Payé",IF($M37="Oui","Litige",IF($O37=0,"À échoir",IF($O37<=30,"0-30",IF($O37<=60,"31-60",IF($O37<=90,"61-90","90+")))))))
I38: =IF($A38="","",SUMIFS(Ventes_Encaissements!$D$6:$D$3005,Ventes_Encaissements!$B$6:$B$3005,$A38)) | J38: =IF($A38="","",$H38-$I38) | K38: =IF($A38="","",IF($I38=0,"",_xludf.AGGREGATE(14,6,Ventes_Encaissements!$C$6:$C$3005/(Ventes_Encaissements!$B$6:$B$3005=$A38),1))) | L38: =IF($A38="","",COUNTIFS(Ventes_Detail!$B$6:$B$3005,$A38)) | N38: =IF($A38="","",IF($G38="","",IF($M38="Oui","Litige",IF($J38<=0,"Payé",IF($I38>0,"Partiel",IF(Listes!$B$3>$G38,"En retard","À échoir")))))) | O38: =IF($A38="","",IF(OR($G38="", $J38<=0),0,MAX(0,Listes!$B$3-$G38))) | P38: =IF($A38="","",IF($J38<=0,"Payé",IF($M38="Oui","Litige",IF($O38=0,"À échoir",IF($O38<=30,"0-30",IF($O38<=60,"31-60",IF($O38<=90,"61-90","90+")))))))
I39: =IF($A39="","",SUMIFS(Ventes_Encaissements!$D$6:$D$3005,Ventes_Encaissements!$B$6:$B$3005,$A39)) | J39: =IF($A39="","",$H39-$I39) | K39: =IF($A39="","",IF($I39=0,"",_xludf.AGGREGATE(14,6,Ventes_Encaissements!$C$6:$C$3005/(Ventes_Encaissements!$B$6:$B$3005=$A39),1))) | L39: =IF($A39="","",COUNTIFS(Ventes_Detail!$B$6:$B$3005,$A39)) | N39: =IF($A39="","",IF($G39="","",IF($M39="Oui","Litige",IF($J39<=0,"Payé",IF($I39>0,"Partiel",IF(Listes!$B$3>$G39,"En retard","À échoir")))))) | O39: =IF($A39="","",IF(OR($G39="", $J39<=0),0,MAX(0,Listes!$B$3-$G39))) | P39: =IF($A39="","",IF($J39<=0,"Payé",IF($M39="Oui","Litige",IF($O39=0,"À échoir",IF($O39<=30,"0-30",IF($O39<=60,"31-60",IF($O39<=90,"61-90","90+")))))))
I40: =IF($A40="","",SUMIFS(Ventes_Encaissements!$D$6:$D$3005,Ventes_Encaissements!$B$6:$B$3005,$A40)) | J40: =IF($A40="","",$H40-$I40) | K40: =IF($A40="","",IF($I40=0,"",_xludf.AGGREGATE(14,6,Ventes_Encaissements!$C$6:$C$3005/(Ventes_Encaissements!$B$6:$B$3005=$A40),1))) | L40: =IF($A40="","",COUNTIFS(Ventes_Detail!$B$6:$B$3005,$A40)) | N40: =IF($A40="","",IF($G40="","",IF($M40="Oui","Litige",IF($J40<=0,"Payé",IF($I40>0,"Partiel",IF(Listes!$B$3>$G40,"En retard","À échoir")))))) | O40: =IF($A40="","",IF(OR($G40="", $J40<=0),0,MAX(0,Listes!$B$3-$G40))) | P40: =IF($A40="","",IF($J40<=0,"Payé",IF($M40="Oui","Litige",IF($O40=0,"À échoir",IF($O40<=30,"0-30",IF($O40<=60,"31-60",IF($O40<=90,"61-90","90+")))))))
...

Sheet Ventes_Encaissements
A1: Échéancier de vente — Encaissements
A2: 1 ligne = 1 paiement (acompte, partiel, solde).
A3: Saisie (bleu) : N° facture, date, montant, banque, moyen. Calcul (gris) : Facture valide ?
A5: ID Encaissement | B5: N° Facture | C5: Date de règlement | D5: Montant réglé (€) | E5: Banque | F5: Moyen | G5: Référence | H5: Commentaire | I5: Facture valide ? | J5: Montant arrondi (€)
I6: =IF($B6="","",IF(COUNTIF(Ventes_Factures!$A$6:$A$3005,$B6)>0,"OK","INCONNUE")) | J6: =IF($D6="","",ROUND($D6,2))
I7: =IF($B7="","",IF(COUNTIF(Ventes_Factures!$A$6:$A$3005,$B7)>0,"OK","INCONNUE")) | J7: =IF($D7="","",ROUND($D7,2))
I8: =IF($B8="","",IF(COUNTIF(Ventes_Factures!$A$6:$A$3005,$B8)>0,"OK","INCONNUE")) | J8: =IF($D8="","",ROUND($D8,2))
I9: =IF($B9="","",IF(COUNTIF(Ventes_Factures!$A$6:$A$3005,$B9)>0,"OK","INCONNUE")) | J9: =IF($D9="","",ROUND($D9,2))
I10: =IF($B10="","",IF(COUNTIF(Ventes_Factures!$A$6:$A$3005,$B10)>0,"OK","INCONNUE")) | J10: =IF($D10="","",ROUND($D10,2))
I11: =IF($B11="","",IF(COUNTIF(Ventes_Factures!$A$6:$A$3005,$B11)>0,"OK","INCONNUE")) | J11: =IF($D11="","",ROUND($D11,2))
I12: =IF($B12="","",IF(COUNTIF(Ventes_Factures!$A$6:$A$3005,$B12)>0,"OK","INCONNUE")) | J12: =IF($D12="","",ROUND($D12,2))
I13: =IF($B13="","",IF(COUNTIF(Ventes_Factures!$A$6:$A$3005,$B13)>0,"OK","INCONNUE")) | J13: =IF($D13="","",ROUND($D13,2))
I14: =IF($B14="","",IF(COUNTIF(Ventes_Factures!$A$6:$A$3005,$B14)>0,"OK","INCONNUE")) | J14: =IF($D14="","",ROUND($D14,2))
I15: =IF($B15="","",IF(COUNTIF(Ventes_Factures!$A$6:$A$3005,$B15)>0,"OK","INCONNUE")) | J15: =IF($D15="","",ROUND($D15,2))
I16: =IF($B16="","",IF(COUNTIF(Ventes_Factures!$A$6:$A$3005,$B16)>0,"OK","INCONNUE")) | J16: =IF($D16="","",ROUND($D16,2))
I17: =IF($B17="","",IF(COUNTIF(Ventes_Factures!$A$6:$A$3005,$B17)>0,"OK","INCONNUE")) | J17: =IF($D17="","",ROUND($D17,2))
... I3005: =IF($B3005="","",IF(COUNTIF(Ventes_Factures!$A$6:$A$3005,$B3005)>0,"OK","INCONNUE")) | J3005: =IF($D3005="","",ROUND($D3005,2))

Sheet Banque_Releve_TEST
A1: Consolidation bancaire — Test de rapprochement (Niveau 1) | M1: Résumé
A2: But : coller/coller les mouvements du relevé bancaire (entrées) et vérifier s'ils correspondent à des encaissements saisis. | M2: Entrées | N2: =COUNTIF($G$6:$G$3005,">0")
A3: Matching : Banque + Montant (entrée) + Date opération ± 3 jours → Match / À vérifier / Non trouvé. | M3: Match | N3: =COUNTIF($I$6:$I$3005,"Match")
M4: À vérifier | N4: =COUNTIF($I$6:$I$3005,"À vérifier")
A5: ID Mouvement | B5: Banque / Compte | C5: Date opération | D5: Date valeur | E5: Libellé | F5: Montant (±) | G5: Montant entrée (+) | H5: Candidats | I5: Statut | J5: N° Facture (si match) | K5: Commentaire | M5: Non trouvé | N5: =COUNTIF($I$6:$I$3005,"Non trouvé")
G6: =IF($F6="","",IF($F6>0,ROUND($F6,2),"")) | H6: =IF(OR($B6="",$C6="",$G6=""),"",COUNTIFS(Ventes_Encaissements!$E$6:$E$3005,$B6,Ventes_Encaissements!$J$6:$J$3005,$G6,Ventes_Encaissements!$C$6:$C$3005,">="&($C6-3),Ventes_Encaissements!$C$6:$C$3005,"<="&($C6+3))) | I6: =IF($H6="","",IF($H6=0,"Non trouvé",IF($H6=1,"Match","À vérifier"))) | J6: =IF($I6<>"Match","",INDEX(Ventes_Encaissements!$B$6:$B$3005,_xludf.AGGREGATE(15,6,(ROW(Ventes_Encaissements!$B$6:$B$3005)-ROW(Ventes_Encaissements!$B$6)+1)/((Ventes_Encaissements!$E$6:$E$3005=$B6)*(Ventes_Encaissements!$J$6:$J$3005=$G6)*(Ventes_Encaissements!$C$6:$C$3005>=$C6-3)*(Ventes_Encaissements!$C$6:$C$3005<=$C6+3)),1)))
G7: =IF($F7="","",IF($F7>0,ROUND($F7,2),"")) | H7: =IF(OR($B7="",$C7="",$G7=""),"",COUNTIFS(Ventes_Encaissements!$E$6:$E$3005,$B7,Ventes_Encaissements!$J$6:$J$3005,$G7,Ventes_Encaissements!$C$6:$C$3005,">="&($C7-3),Ventes_Encaissements!$C$6:$C$3005,"<="&($C7+3))) | I7: =IF($H7="","",IF($H7=0,"Non trouvé",IF($H7=1,"Match","À vérifier"))) | J7: =IF($I7<>"Match","",INDEX(Ventes_Encaissements!$B$6:$B$3005,_xludf.AGGREGATE(15,6,(ROW(Ventes_Encaissements!$B$6:$B$3005)-ROW(Ventes_Encaissements!$B$6)+1)/((Ventes_Encaissements!$E$6:$E$3005=$B7)*(Ventes_Encaissements!$J$6:$J$3005=$G7)*(Ventes_Encaissements!$C$6:$C$3005>=$C7-3)*(Ventes_Encaissements!$C$6:$C$3005<=$C7+3)),1)))
G8: =IF($F8="","",IF($F8>0,ROUND($F8,2),"")) | H8: =IF(OR($B8="",$C8="",$G8=""),"",COUNTIFS(Ventes_Encaissements!$E$6:$E$3005,$B8,Ventes_Encaissements!$J$6:$J$3005,$G8,Ventes_Encaissements!$C$6:$C$3005,">="&($C8-3),Ventes_Encaissements!$C$6:$C$3005,"<="&($C8+3))) | I8: =IF($H8="","",IF($H8=0,"Non trouvé",IF($H8=1,"Match","À vérifier"))) | J8: =IF($I8<>"Match","",INDEX(Ventes_Encaissements!$B$6:$B$3005,_xludf.AGGREGATE(15,6,(ROW(Ventes_Encaissements!$B$6:$B$3005)-ROW(Ventes_Encaissements!$B$6)+1)/((Ventes_Encaissements!$E$6:$E$3005=$B8)*(Ventes_Encaissements!$J$6:$J$3005=$G8)*(Ventes_Encaissements!$C$6:$C$3005>=$C8-3)*(Ventes_Encaissements!$C$6:$C$3005<=$C8+3)),1)))
G9: =IF($F9="","",IF($F9>0,ROUND($F9,2),"")) | H9: =IF(OR($B9="",$C9="",$G9=""),"",COUNTIFS(Ventes_Encaissements!$E$6:$E$3005,$B9,Ventes_Encaissements!$J$6:$J$3005,$G9,Ventes_Encaissements!$C$6:$C$3005,">="&($C9-3),Ventes_Encaissements!$C$6:$C$3005,"<="&($C9+3))) | I9: =IF($H9="","",IF($H9=0,"Non trouvé",IF($H9=1,"Match","À vérifier"))) | J9: =IF($I9<>"Match","",INDEX(Ventes_Encaissements!$B$6:$B$3005,_xludf.AGGREGATE(15,6,(ROW(Ventes_Encaissements!$B$6:$B$3005)-ROW(Ventes_Encaissements!$B$6)+1)/((Ventes_Encaissements!$E$6:$E$3005=$B9)*(Ventes_Encaissements!$J$6:$J$3005=$G9)*(Ventes_Encaissements!$C$6:$C$3005>=$C9-3)*(Ventes_Encaissements!$C$6:$C$3005<=$C9+3)),1)))
G10: =IF($F10="","",IF($F10>0,ROUND($F10,2),"")) | H10: =IF(OR($B10="",$C10="",$G10=""),"",COUNTIFS(Ventes_Encaissements!$E$6:$E$3005,$B10,Ventes_Encaissements!$J$6:$J$3005,$G10,Ventes_Encaissements!$C$6:$C$3005,">="&($C10-3),Ventes_Encaissements!$C$6:$C$3005,"<="&($C10+3))) | I10: =IF($H10="","",IF($H10=0,"Non trouvé",IF($H10=1,"Match","À vérifier"))) | J10: =IF($I10<>"Match","",INDEX(Ventes_Encaissements!$B$6:$B$3005,_xludf.AGGREGATE(15,6,(ROW(Ventes_Encaissements!$B$6:$B$3005)-ROW(Ventes_Encaissements!$B$6)+1)/((Ventes_Encaissements!$E$6:$E$3005=$B10)*(Ventes_Encaissements!$J$6:$J$3005=$G10)*(Ventes_Encaissements!$C$6:$C$3005>=$C10-3)*(Ventes_Encaissements!$C$6:$C$3005<=$C10+3)),1)))
G11: =IF($F11="","",IF($F11>0,ROUND($F11,2),"")) | H11: =IF(OR($B11="",$C11="",$G11=""),"",COUNTIFS(Ventes_Encaissements!$E$6:$E$3005,$B11,Ventes_Encaissements!$J$6:$J$3005,$G11,Ventes_Encaissements!$C$6:$C$3005,">="&($C11-3),Ventes_Encaissements!$C$6:$C$3005,"<="&($C11+3))) | I11: =IF($H11="","",IF($H11=0,"Non trouvé",IF($H11=1,"Match","À vérifier"))) | J11: =IF($I11<>"Match","",INDEX(Ventes_Encaissements!$B$6:$B$3005,_xludf.AGGREGATE(15,6,(ROW(Ventes_Encaissements!$B$6:$B$3005)-ROW(Ventes_Encaissements!$B$6)+1)/((Ventes_Encaissements!$E$6:$E$3005=$B11)*(Ventes_Encaissements!$J$6:$J$3005=$G11)*(Ventes_Encaissements!$C$6:$C$3005>=$C11-3)*(Ventes_Encaissements!$C$6:$C$3005<=$C11+3)),1)))
G12: =IF($F12="","",IF($F12>0,ROUND($F12,2),"")) | H12: =IF(OR($B12="",$C12="",$G12=""),"",COUNTIFS(Ventes_Encaissements!$E$6:$E$3005,$B12,Ventes_Encaissements!$J$6:$J$3005,$G12,Ventes_Encaissements!$C$6:$C$3005,">="&($C12-3),Ventes_Encaissements!$C$6:$C$3005,"<="&($C12+3))) | I12: =IF($H12="","",IF($H12=0,"Non trouvé",IF($H12=1,"Match","À vérifier"))) | J12: =IF($I12<>"Match","",INDEX(Ventes_Encaissements!$B$6:$B$3005,_xludf.AGGREGATE(15,6,(ROW(Ventes_Encaissements!$B$6:$B$3005)-ROW(Ventes_Encaissements!$B$6)+1)/((Ventes_Encaissements!$E$6:$E$3005=$B12)*(Ventes_Encaissements!$J$6:$J$3005=$G12)*(Ventes_Encaissements!$C$6:$C$3005>=$C12-3)*(Ventes_Encaissements!$C$6:$C$3005<=$C12+3)),1)))
G13: =IF($F13="","",IF($F13>0,ROUND($F13,2),"")) | H13: =IF(OR($B13="",$C13="",$G13=""),"",COUNTIFS(Ventes_Encaissements!$E$6:$E$3005,$B13,Ventes_Encaissements!$J$6:$J$3005,$G13,Ventes_Encaissements!$C$6:$C$3005,">="&($C13-3),Ventes_Encaissements!$C$6:$C$3005,"<="&($C13+3))) | I13: =IF($H13="","",IF($H13=0,"Non trouvé",IF($H13=1,"Match","À vérifier"))) | J13: =IF($I13<>"Match","",INDEX(Ventes_Encaissements!$B$6:$B$3005,_xludf.AGGREGATE(15,6,(ROW(Ventes_Encaissements!$B$6:$B$3005)-ROW(Ventes_Encaissements!$B$6)+1)/((Ventes_Encaissements!$E$6:$E$3005=$B13)*(Ventes_Encaissements!$J$6:$J$3005=$G13)*(Ventes_Encaissements!$C$6:$C$3005>=$C13-3)*(Ventes_Encaissements!$C$6:$C$3005<=$C13+3)),1)))
G14: =IF($F14="","",IF($F14>0,ROUND($F14,2),"")) | H14: =IF(OR($B14="",$C14="",$G14=""),"",COUNTIFS(Ventes_Encaissements!$E$6:$E$3005,$B14,Ventes_Encaissements!$J$6:$J$3005,$G14,Ventes_Encaissements!$C$6:$C$3005,">="&($C14-3),Ventes_Encaissements!$C$6:$C$3005,"<="&($C14+3))) | I14: =IF($H14="","",IF($H14=0,"Non trouvé",IF($H14=1,"Match","À vérifier"))) | J14: =IF($I14<>"Match","",INDEX(Ventes_Encaissements!$B$6:$B$3005,_xludf.AGGREGATE(15,6,(ROW(Ventes_Encaissements!$B$6:$B$3005)-ROW(Ventes_Encaissements!$B$6)+1)/((Ventes_Encaissements!$E$6:$E$3005=$B14)*(Ventes_Encaissements!$J$6:$J$3005=$G14)*(Ventes_Encaissements!$C$6:$C$3005>=$C14-3)*(Ventes_Encaissements!$C$6:$C$3005<=$C14+3)),1)))
G15: =IF($F15="","",IF($F15>0,ROUND($F15,2),"")) | H15: =IF(OR($B15="",$C15="",$G15=""),"",COUNTIFS(Ventes_Encaissements!$E$6:$E$3005,$B15,Ventes_Encaissements!$J$6:$J$3005,$G15,Ventes_Encaissements!$C$6:$C$3005,">="&($C15-3),Ventes_Encaissements!$C$6:$C$3005,"<="&($C15+3))) | I15: =IF($H15="","",IF($H15=0,"Non trouvé",IF($H15=1,"Match","À vérifier"))) | J15: =IF($I15<>"Match","",INDEX(Ventes_Encaissements!$B$6:$B$3005,_xludf.AGGREGATE(15,6,(ROW(Ventes_Encaissements!$B$6:$B$3005)-ROW(Ventes_Encaissements!$B$6)+1)/((Ventes_Encaissements!$E$6:$E$3005=$B15)*(Ventes_Encaissements!$J$6:$J$3005=$G15)*(Ventes_Encaissements!$C$6:$C$3005>=$C15-3)*(Ventes_Encaissements!$C$6:$C$3005<=$C15+3)),1)))
G16: =IF($F16="","",IF($F16>0,ROUND($F16,2),"")) | H16: =IF(OR($B16="",$C16="",$G16=""),"",COUNTIFS(Ventes_Encaissements!$E$6:$E$3005,$B16,Ventes_Encaissements!$J$6:$J$3005,$G16,Ventes_Encaissements!$C$6:$C$3005,">="&($C16-3),Ventes_Encaissements!$C$6:$C$3005,"<="&($C16+3))) | I16: =IF($H16="","",IF($H16=0,"Non trouvé",IF($H16=1,"Match","À vérifier"))) | J16: =IF($I16<>"Match","",INDEX(Ventes_Encaissements!$B$6:$B$3005,_xludf.AGGREGATE(15,6,(ROW(Ventes_Encaissements!$B$6:$B$3005)-ROW(Ventes_Encaissements!$B$6)+1)/((Ventes_Encaissements!$E$6:$E$3005=$B16)*(Ventes_Encaissements!$J$6:$J$3005=$G16)*(Ventes_Encaissements!$C$6:$C$3005>=$C16-3)*(Ventes_Encaissements!$C$6:$C$3005<=$C16+3)),1)))
G17: =IF($F17="","",IF($F17>0,ROUND($F17,2),"")) | H17: =IF(OR($B17="",$C17="",$G17=""),"",COUNTIFS(Ventes_Encaissements!$E$6:$E$3005,$B17,Ventes_Encaissements!$J$6:$J$3005,$G17,Ventes_Encaissements!$C$6:$C$3005,">="&($C17-3),Ventes_Encaissements!$C$6:$C$3005,"<="&($C17+3))) | I17: =IF($H17="","",IF($H17=0,"Non trouvé",IF($H17=1,"Match","À vérifier"))) | J17: =IF($I17<>"Match","",INDEX(Ventes_Encaissements!$B$6:$B$3005,_xludf.AGGREGATE(15,6,(ROW(Ventes_Encaissements!$B$6:$B$3005)-ROW(Ventes_Encaissements!$B$6)+1)/((Ventes_Encaissements!$E$6:$E$3005=$B17)*(Ventes_Encaissements!$J$6:$J$3005=$G17)*(Ventes_Encaissements!$C$6:$C$3005>=$C17-3)*(Ventes_Encaissements!$C$6:$C$3005<=$C17+3)),1)))
... G3005: =IF($F3005="","",IF($F3005>0,ROUND($F3005,2),"")) | H3005: =IF(OR($B3005="",$C3005="",$G3005=""),"",COUNTIFS(Ventes_Encaissements!$E$6:$E$3005,$B3005,Ventes_Encaissements!$J$6:$J$3005,$G3005,Ventes_Encaissements!$C$6:$C$3005,">="&($C3005-3),Ventes_Encaissements!$C$6:$C$3005,"<="&($C3005+3))) | I3005: =IF($H3005="","",IF($H3005=0,"Non trouvé",IF($H3005=1,"Match","À vérifier"))) | J3005: =IF($I3005<>"Match","",INDEX(Ventes_Encaissements!$B$6:$B$3005,_xludf.AGGREGATE(15,6,(ROW(Ventes_Encaissements!$B$6:$B$3005)-ROW(Ventes_Encaissements!$B$6)+1)/((Ventes_Encaissements!$E$6:$E$3005=$B3005)*(Ventes_Encaissements!$J$6:$J$3005=$G3005)*(Ventes_Encaissements!$C$6:$C$3005>=$C3005-3)*(Ventes_Encaissements!$C$6:$C$3005<=$C3005+3)),1)))

Sheet Ventes_Detail
A1: Échéancier de vente — Détail stagiaires
A2: B2C : 1 ligne / facture. B2B : plusieurs lignes / facture.
A3: Astuce : filtrer par N° facture pour retrouver la liste des stagiaires.
A5: ID Détail | B5: N° Facture | C5: Stagiaire | D5: Session | E5: Montant imputé (€) | F5: Commentaire

Sheet Synthèse
A1: Synthèse — Échéancier de vente
A2: Montants basés sur « Reste à encaisser ». La Date de référence se modifie dans la feuille Listes.
A4: KPIs
A5: Indicateur | B5: Montant (€) | C5: Nb factures
A6: Montant en retard | B6: =SUMIFS(Ventes_Factures!$J$6:$J$3005,Ventes_Factures!$N$6:$N$3005,"En retard") | C6: =COUNTIFS(Ventes_Factures!$N$6:$N$3005,"En retard",Ventes_Factures!$A$6:$A$3005,"<>")
A7: Montant à échoir | B7: =SUMIFS(Ventes_Factures!$J$6:$J$3005,Ventes_Factures!$N$6:$N$3005,"À échoir") | C7: =COUNTIFS(Ventes_Factures!$N$6:$N$3005,"À échoir",Ventes_Factures!$A$6:$A$3005,"<>")
A8: Montant en litige | B8: =SUMIFS(Ventes_Factures!$J$6:$J$3005,Ventes_Factures!$N$6:$N$3005,"Litige") | C8: =COUNTIFS(Ventes_Factures!$N$6:$N$3005,"Litige",Ventes_Factures!$A$6:$A$3005,"<>")
A10: Aging (En retard)
A11: Bucket | B11: Montant (€) | C11: Nb factures
A12: 0-30 | B12: =SUMIFS(Ventes_Factures!$J$6:$J$3005,Ventes_Factures!$P$6:$P$3005,"0-30",Ventes_Factures!$N$6:$N$3005,"En retard") | C12: =COUNTIFS(Ventes_Factures!$P$6:$P$3005,"0-30",Ventes_Factures!$N$6:$N$3005,"En retard",Ventes_Factures!$A$6:$A$3005,"<>")
A13: 31-60 | B13: =SUMIFS(Ventes_Factures!$J$6:$J$3005,Ventes_Factures!$P$6:$P$3005,"31-60",Ventes_Factures!$N$6:$N$3005,"En retard") | C13: =COUNTIFS(Ventes_Factures!$P$6:$P$3005,"31-60",Ventes_Factures!$N$6:$N$3005,"En retard",Ventes_Factures!$A$6:$A$3005,"<>")
A14: 61-90 | B14: =SUMIFS(Ventes_Factures!$J$6:$J$3005,Ventes_Factures!$P$6:$P$3005,"61-90",Ventes_Factures!$N$6:$N$3005,"En retard") | C14: =COUNTIFS(Ventes_Factures!$P$6:$P$3005,"61-90",Ventes_Factures!$N$6:$N$3005,"En retard",Ventes_Factures!$A$6:$A$3005,"<>")
A15: 90+ | B15: =SUMIFS(Ventes_Factures!$J$6:$J$3005,Ventes_Factures!$P$6:$P$3005,"90+",Ventes_Factures!$N$6:$N$3005,"En retard") | C15: =COUNTIFS(Ventes_Factures!$P$6:$P$3005,"90+",Ventes_Factures!$N$6:$N$3005,"En retard",Ventes_Factures!$A$6:$A$3005,"<>")
A16: Prévision d'encaissements — par semaine (12 semaines)
A17: Semaine | B17: Début semaine | C17: Fin semaine | D17: Montant dû (€)
A18: ="S"&WEEKNUM($B18,21)&" "&TEXT($B18-WEEKDAY($B18,2)+4,"yyyy") | B18: =Listes!$B$3-WEEKDAY(Listes!$B$3,2)+1 | C18: =B18+6 | D18: =SUMIFS(Ventes_Factures!$J$6:$J$3005,Ventes_Factures!$G$6:$G$3005,">="&B18,Ventes_Factures!$G$6:$G$3005,"<="&C18,Ventes_Factures!$N$6:$N$3005,"<>Payé",Ventes_Factures!$N$6:$N$3005,"<>Litige")
A19: ="S"&WEEKNUM($B19,21)&" "&TEXT($B19-WEEKDAY($B19,2)+4,"yyyy") | B19: =B18+7 | C19: =C18+7 | D19: =SUMIFS(Ventes_Factures!$J$6:$J$3005,Ventes_Factures!$G$6:$G$3005,">="&B19,Ventes_Factures!$G$6:$G$3005,"<="&C19,Ventes_Factures!$N$6:$N$3005,"<>Payé",Ventes_Factures!$N$6:$N$3005,"<>Litige")
A20: ="S"&WEEKNUM($B20,21)&" "&TEXT($B20-WEEKDAY($B20,2)+4,"yyyy") | B20: =B19+7 | C20: =C19+7 | D20: =SUMIFS(Ventes_Factures!$J$6:$J$3005,Ventes_Factures!$G$6:$G$3005,">="&B20,Ventes_Factures!$G$6:$G$3005,"<="&C20,Ventes_Factures!$N$6:$N$3005,"<>Payé",Ventes_Factures!$N$6:$N$3005,"<>Litige")
A21: ="S"&WEEKNUM($B21,21)&" "&TEXT($B21-WEEKDAY($B21,2)+4,"yyyy") | B21: =B20+7 | C21: =C20+7 | D21: =SUMIFS(Ventes_Factures!$J$6:$J$3005,Ventes_Factures!$G$6:$G$3005,">="&B21,Ventes_Factures!$G$6:$G$3005,"<="&C21,Ventes_Factures!$N$6:$N$3005,"<>Payé",Ventes_Factures!$N$6:$N$3005,"<>Litige")
A22: ="S"&WEEKNUM($B22,21)&" "&TEXT($B22-WEEKDAY($B22,2)+4,"yyyy") | B22: =B21+7 | C22: =C21+7 | D22: =SUMIFS(Ventes_Factures!$J$6:$J$3005,Ventes_Factures!$G$6:$G$3005,">="&B22,Ventes_Factures!$G$6:$G$3005,"<="&C22,Ventes_Factures!$N$6:$N$3005,"<>Payé",Ventes_Factures!$N$6:$N$3005,"<>Litige")
A23: ="S"&WEEKNUM($B23,21)&" "&TEXT($B23-WEEKDAY($B23,2)+4,"yyyy") | B23: =B22+7 | C23: =C22+7 | D23: =SUMIFS(Ventes_Factures!$J$6:$J$3005,Ventes_Factures!$G$6:$G$3005,">="&B23,Ventes_Factures!$G$6:$G$3005,"<="&C23,Ventes_Factures!$N$6:$N$3005,"<>Payé",Ventes_Factures!$N$6:$N$3005,"<>Litige")
A24: ="S"&WEEKNUM($B24,21)&" "&TEXT($B24-WEEKDAY($B24,2)+4,"yyyy") | B24: =B23+7 | C24: =C23+7 | D24: =SUMIFS(Ventes_Factures!$J$6:$J$3005,Ventes_Factures!$G$6:$G$3005,">="&B24,Ventes_Factures!$G$6:$G$3005,"<="&C24,Ventes_Factures!$N$6:$N$3005,"<>Payé",Ventes_Factures!$N$6:$N$3005,"<>Litige")
A25: ="S"&WEEKNUM($B25,21)&" "&TEXT($B25-WEEKDAY($B25,2)+4,"yyyy") | B25: =B24+7 | C25: =C24+7 | D25: =SUMIFS(Ventes_Factures!$J$6:$J$3005,Ventes_Factures!$G$6:$G$3005,">="&B25,Ventes_Factures!$G$6:$G$3005,"<="&C25,Ventes_Factures!$N$6:$N$3005,"<>Payé",Ventes_Factures!$N$6:$N$3005,"<>Litige")
A26: ="S"&WEEKNUM($B26,21)&" "&TEXT($B26-WEEKDAY($B26,2)+4,"yyyy") | B26: =B25+7 | C26: =C25+7 | D26: =SUMIFS(Ventes_Factures!$J$6:$J$3005,Ventes_Factures!$G$6:$G$3005,">="&B26,Ventes_Factures!$G$6:$G$3005,"<="&C26,Ventes_Factures!$N$6:$N$3005,"<>Payé",Ventes_Factures!$N$6:$N$3005,"<>Litige")
A27: ="S"&WEEKNUM($B27,21)&" "&TEXT($B27-WEEKDAY($B27,2)+4,"yyyy") | B27: =B26+7 | C27: =C26+7 | D27: =SUMIFS(Ventes_Factures!$J$6:$J$3005,Ventes_Factures!$G$6:$G$3005,">="&B27,Ventes_Factures!$G$6:$G$3005,"<="&C27,Ventes_Factures!$N$6:$N$3005,"<>Payé",Ventes_Factures!$N$6:$N$3005,"<>Litige")
A28: ="S"&WEEKNUM($B28,21)&" "&TEXT($B28-WEEKDAY($B28,2)+4,"yyyy") | B28: =B27+7 | C28: =C27+7 | D28: =SUMIFS(Ventes_Factures!$J$6:$J$3005,Ventes_Factures!$G$6:$G$3005,">="&B28,Ventes_Factures!$G$6:$G$3005,"<="&C28,Ventes_Factures!$N$6:$N$3005,"<>Payé",Ventes_Factures!$N$6:$N$3005,"<>Litige")
A29: ="S"&WEEKNUM($B29,21)&" "&TEXT($B29-WEEKDAY($B29,2)+4,"yyyy") | B29: =B28+7 | C29: =C28+7 | D29: =SUMIFS(Ventes_Factures!$J$6:$J$3005,Ventes_Factures!$G$6:$G$3005,">="&B29,Ventes_Factures!$G$6:$G$3005,"<="&C29,Ventes_Factures!$N$6:$N$3005,"<>Payé",Ventes_Factures!$N$6:$N$3005,"<>Litige")
A31: Note : la prévision hebdo exclut les factures 'Payé' et 'Litige' (cash prévisible).

Sheet Qualité
A1: Contrôles qualité
A2: Si le statut est « À CORRIGER », corrige l’anomalie indiquée (colonne Action).
A4: Contrôle | B4: Nb | C4: Statut | D4: Action
A5: Factures sans client | B5: =COUNTIFS(Ventes_Factures!$A$6:$A$3005,"<>",Ventes_Factures!$B$6:$B$3005,"") | C5: =IF($B5=0,"OK","À CORRIGER") | D5: =HYPERLINK("#'Ventes_Factures'!B1", "Aller vers Factures")
A6: Factures sans date facture | B6: =COUNTIFS(Ventes_Factures!$A$6:$A$3005,"<>",Ventes_Factures!$F$6:$F$3005,"") | C6: =IF($B6=0,"OK","À CORRIGER") | D6: Compléter Date Facture
A7: Factures sans échéance | B7: =COUNTIFS(Ventes_Factures!$A$6:$A$3005,"<>",Ventes_Factures!$G$6:$G$3005,"") | C7: =IF($B7=0,"OK","À CORRIGER") | D7: Compléter Échéance
A8: Factures B2B sans détail stagiaire | B8: =COUNTIFS(Ventes_Factures!$C$6:$C$3005,"B2B",Ventes_Factures!$L$6:$L$3005,0,Ventes_Factures!$A$6:$A$3005,"<>") | C8: =IF($B8=0,"OK","À CORRIGER") | D8: Remplir Ventes_Detail
A9: Encaissements sans N° facture | B9: =COUNTIFS(Ventes_Encaissements!$D$6:$D$3005,"<>",Ventes_Encaissements!$B$6:$B$3005,"") | C9: =IF($B9=0,"OK","À CORRIGER") | D9: Renseigner N° facture
A10: Encaissements avec facture inconnue | B10: =COUNTIF(Ventes_Encaissements!$I$6:$I$3005,"INCONNUE") | C10: =IF($B10=0,"OK","À CORRIGER") | D10: =HYPERLINK("#'Ventes_Factures'!A1", "Corriger l’ID facture")
A11: Reste à encaisser négatif (sur-encaissement) | B11: =COUNTIF(Ventes_Factures!$J$6:$J$3005,"<0") | C11: =IF($B11=0,"OK","À CORRIGER") | D11: Vérifier paiements
